Workbook

Sheet 0-使用说明
A1: AI 客服 ROI 测算模板 - 使用说明
A3: # | B3: 项目 | C3: 说明
B4: 使用步骤
B5: Step 1 | C5: 打开 [1-输入参数] 页，填写绿色格子。这是唯一需要改的页。
B6: Step 2 | C6: 查看 [2-现状基线] 页，确认你当前的人工客服成本结构是否符合实际。
B7: Step 3 | C7: 查看 [3-AI改造后测算] 页，看到整体降本效果与新单位成本。
B8: Step 4 | C8: 查看 [4-分场景收益] 页，定位哪些场景贡献最大，决定立项优先级。
B9: Step 5 | C9: 查看 [5-三年现金流ROI] 页，向 CFO / 老板汇报用这张。
B10: Step 6 | C10: 查看 [6-敏感性分析] 页，回答'如果 AI 承接率只做到 50% 怎么办'这类问题。
B11: Step 7 | C11: 查看 [7-Dashboard] 页，一页纸汇报用。
B13: 颜色图例
B14: 绿色格子 | C14: 输入项，只改这些。
B15: 黄色格子 | C15: 公式计算项，不要手改，会破坏联动。
B16: 橙色格子 | C16: 关键结果，重点看。
B17: 灰色格子 | C17: 备注和参考值。
B19: 行业经验参考值
B20: 单次人工会话成本 | C20: 电商 3~6 元 / 金融 6~15 元 / 运营商 4~8 元
B21: 单次 AI 自助成本 | C21: 0.1~0.5 元（含 Token + 平台摊销）
B22: AI 承接率（1 年目标） | C22: 首期 30%~50%，成熟期 60%~80%
B23: AHT 降幅（Copilot 场景） | C23: 15%~30%
B24: 质检覆盖率提升 | C24: 5% → 100%，质检人员可压缩 60%~80%
B25: FCR 提升 | C25: 3~8 个百分点
B27: 注意事项
B28: 注意 1 | C28: 人力成本按全口径（工资+社保+场地+管理+流失成本），一般为裸工资 × 1.5~1.8。
B29: 注意 2 | C29: AI 成本要含：大模型 API / GPU 摊销 / 平台软件 / AI 训练师人力 / 实施外包。
B30: 注意 3 | C30: 不要只看第一年，大模型项目第 2-3 年规模化才是 ROI 主要来源。
B31: 注意 4 | C31: CSAT、NPS 的提升很难折现，本模板默认不算入财务收益，作为软性收益单独列示。

Sheet 1-输入参数
A1: 1. 输入参数（绿色格子 = 需要你填）
A3: # | B3: 参数名称 | C3: 数值 | D3: 单位 | E3: 说明 / 参考
A4: A. 业务规模基线
B5: 月均会话量 | C5: 1000000 | D5: 次/月 | E5: 含在线+电话+工单，全渠道合计
B6: 人工坐席数 | C6: 1500 | D6: 人 | E6: 一线坐席，不含质检/主管
B7: 质检人员数 | C7: 80 | D7: 人 | E7: 原有质检团队规模
B8: 坐席月均工时 | C8: 176 | D8: 小时/人/月 | E8: 按每月22天 × 8小时
A9: B. 人工成本（全口径）
B10: 坐席月均全成本 | C10: 8000 | D10: 元/人/月 | E10: 裸工资 × 1.5~1.8（含社保、场地、管理摊销）
B11: 质检员月均全成本 | C11: 10000 | D11: 元/人/月 | E11: 一般高于坐席 20%
B12: 主管/运营人员数 | C12: 100 | D12: 人 | E12: 不直接参与对话但与规模挂钩
B13: 主管/运营月均全成本 | C13: 15000 | D13: 元/人/月
A14: C. 现状 KPI
B15: 现有机器人承接率 | C15: 0.15 | D15: % | E15: 老一代规则机器人的自助率
B16: 平均会话时长 AHT | C16: 8 | D16: 分钟/次 | E16: 人工会话平均处理时长
B17: 事后处理时长 ACW | C17: 3 | D17: 分钟/次 | E17: 会话结束后填单/记录的时长
B18: 一解率 FCR | C18: 0.65 | D18: % | E18: 一次咨询解决率
B19: 质检覆盖率 | C19: 0.05 | D19: % | E19: 抽检比例
B20: CSAT 满意度 | C20: 0.82 | D20: % | E20: 当前客户满意度
A21: D. AI 方案目标（Y1/Y2/Y3）
B22: AI 承接率 Y1 | C22: 0.35 | D22: % | E22: 第 1 年目标，典型 30%~50%
B23: AI 承接率 Y2 | C23: 0.55 | D23: % | E23: 第 2 年
B24: AI 承接率 Y3 | C24: 0.7 | D24: % | E24: 第 3 年，成熟期
B25: Copilot 覆盖坐席比例 Y1 | C25: 0.6 | D25: % | E25: 多少比例的坐席使用 Copilot
B26: Copilot 覆盖坐席比例 Y2 | C26: 0.9 | D26: %
B27: Copilot 覆盖坐席比例 Y3 | C27: 1 | D27: %
B28: Copilot 带来 AHT 降幅 | C28: 0.2 | D28: % | E28: 15%~30%
B29: Copilot 带来 ACW 降幅 | C29: 0.5 | D29: % | E29: 工单自动生成后降幅 40%~60%
B30: AI 质检覆盖率 | C30: 1 | D30: % | E30: AI 质检一般做到 100%
B31: AI 质检员压缩比例 | C31: 0.7 | D31: % | E31: 60%~80%
B32: FCR 提升（百分点） | C32: 0.05 | D32: % | E32: 3~8 个百分点
A33: E. AI 成本
B34: 单次 AI 会话成本 | C34: 0.3 | D34: 元/次 | E34: 含 Token + 平台摊销，0.1~0.5
B35: AI 平台年订阅/摊销 | C35: 1500000 | D35: 元/年 | E35: 大模型私有化 / SaaS 订阅 / GPU 摊销
B36: 一次性建设投入 | C36: 3000000 | D36: 元 | E36: 项目实施+定制开发+数据治理，第 0 年投入
B37: AI 训练师/运营人数 | C37: 8 | D37: 人 | E37: 新增岗位
B38: AI 训练师月均全成本 | C38: 18000 | D38: 元/人/月
B39: 年度模型维护/迭代费 | C39: 800000 | D39: 元/年 | E39: 持续调优、知识运营
A40: F. 软性收益（可选）
B41: CSAT 每提升 1pp 带来留存收入增量 | C41: 500000 | D41: 元/年 | E41: 仅做估算，不计入主 ROI
...

Sheet 2-现状基线
A1: 2. 现状基线（改造前）
A3: # | B3: 指标 | C3: 数值 | D3: 单位 | E3: 口径说明
A4: 1 | B4: 年会话量 | C4: ='1-输入参数'!$C$5*12 | D4: 次/年 | E4: 月均×12
A5: 2 | B5: 人工承接量（年） | C5: ='1-输入参数'!$C$5*12*(1-'1-输入参数'!$C$15) | D5: 次/年 | E5: 扣除旧机器人自助
A6: 3 | B6: 坐席年人力成本 | C6: ='1-输入参数'!$C$6*'1-输入参数'!$C$10*12 | D6: 元/年 | E6: 坐席×月成本×12
A7: 4 | B7: 质检年人力成本 | C7: ='1-输入参数'!$C$7*'1-输入参数'!$C$11*12 | D7: 元/年 | E7: 质检×月成本×12
A8: 5 | B8: 主管年人力成本 | C8: ='1-输入参数'!$C$12*'1-输入参数'!$C$13*12 | D8: 元/年 | E8: 主管×月成本×12
A9: 6 | B9: 年人工总成本 | C9: =C6+C7+C8 | D9: 元/年 | E9: 坐席+质检+主管
A10: 7 | B10: 单次人工会话成本 | C10: =C9/C4 | D10: 元/次 | E10: 年人工成本 ÷ 年会话量（全口径）
A11: 8 | B11: 单次人工会话成本(仅坐席) | C11: =C6/C4 | D11: 元/次 | E11: 仅坐席摊销口径
A12: 9 | B12: 平均处理时长(AHT+ACW) | C12: ='1-输入参数'!$C$16+'1-输入参数'!$C$17 | D12: 分钟/次 | E12: 处理+事后
A13: 10 | B13: 年坐席总工时 | C13: ='1-输入参数'!$C$6*'1-输入参数'!$C$8*12 | D13: 人时/年
A14: 11 | B14: 人均日均会话量 | C14: =C4/'1-输入参数'!$C$6/250 | D14: 次/人/日 | E14: 按年 250 个工作日
A15: 12 | B15: FCR | C15: ='1-输入参数'!$C$18 | D15: % | E15: 一解率
A16: 13 | B16: 质检覆盖率 | C16: ='1-输入参数'!$C$19 | D16: % | E16: 抽检比例
A17: 14 | B17: CSAT | C17: ='1-输入参数'!$C$20 | D17: %

Sheet 3-AI改造后测算
A1: 3. AI 改造后测算（Y1 / Y2 / Y3）
A3: 指标 | B3: Y1 | C3: Y2 | D3: Y3 | E3: 备注
A4: 年会话量 | B4: ='2-现状基线'!$C$4 | C4: ='2-现状基线'!$C$4 | D4: ='2-现状基线'!$C$4 | E4: 与基线相同
A5: AI 承接率 | B5: ='1-输入参数'!$C$22 | C5: ='1-输入参数'!$C$23 | D5: ='1-输入参数'!$C$24 | E5: 目标值
A6: AI 自助会话量 | B6: =B4*B5 | C6: =C4*C5 | D6: =D4*D5 | E6: 年会话×AI承接率
A7: 人工承接会话量 | B7: =B4*(1-B5) | C7: =C4*(1-C5) | D7: =D4*(1-D5) | E7: 剩余由人工处理
A8: 人工承接需坐席数（基准AHT） | B8: =B7*('1-输入参数'!$C$16+'1-输入参数'!$C$17)/60/('1-输入参数'!$C$8*12) | C8: =C7*('1-输入参数'!$C$16+'1-输入参数'!$C$17)/60/('1-输入参数'!$C$8*12) | D8: =D7*('1-输入参数'!$C$16+'1-输入参数'!$C$17)/60/('1-输入参数'!$C$8*12) | E8: (会话量×处理时长/60) ÷ 人均年工时，基准口径
A9: Copilot 加权 AHT+ACW | B9: ='1-输入参数'!$C$16*(1-'1-输入参数'!$C$25*'1-输入参数'!$C$28)+'1-输入参数'!$C$17*(1-'1-输入参数'!$C$25*'1-输入参数'!$C$29) | C9: ='1-输入参数'!$C$16*(1-'1-输入参数'!$C$26*'1-输入参数'!$C$28)+'1-输入参数'!$C$17*(1-'1-输入参数'!$C$26*'1-输入参数'!$C$29) | D9: ='1-输入参数'!$C$16*(1-'1-输入参数'!$C$27*'1-输入参数'!$C$28)+'1-输入参数'!$C$17*(1-'1-输入参数'!$C$27*'1-输入参数'!$C$29) | E9: Copilot 覆盖率×降幅
A10: 实际需坐席数 | B10: =B7*B9/60/('1-输入参数'!$C$8*12) | C10: =C7*C9/60/('1-输入参数'!$C$8*12) | D10: =D7*D9/60/('1-输入参数'!$C$8*12) | E10: 结合 Copilot 后的真实需求
A11: 可压缩坐席数 | B11: ='1-输入参数'!$C$6-B10 | C11: ='1-输入参数'!$C$6-C10 | D11: ='1-输入参数'!$C$6-D10 | E11: 基准坐席 - 实际需坐席
A12: 坐席年成本（改造后） | B12: =B10*'1-输入参数'!$C$10*12 | C12: =C10*'1-输入参数'!$C$10*12 | D12: =D10*'1-输入参数'!$C$10*12
A13: 质检人员（改造后） | B13: ='1-输入参数'!$C$7*(1-'1-输入参数'!$C$31) | C13: ='1-输入参数'!$C$7*(1-'1-输入参数'!$C$31) | D13: ='1-输入参数'!$C$7*(1-'1-输入参数'!$C$31)
A14: 质检年成本（改造后） | B14: =B13*'1-输入参数'!$C$11*12 | C14: =C13*'1-输入参数'!$C$11*12 | D14: =D13*'1-输入参数'!$C$11*12
A15: 主管年成本（按坐席比例缩放） | B15: ='2-现状基线'!$C$8*B10/'1-输入参数'!$C$6 | C15: ='2-现状基线'!$C$8*C10/'1-输入参数'!$C$6 | D15: ='2-现状基线'!$C$8*D10/'1-输入参数'!$C$6 | E15: 主管规模随坐席等比例缩减
A16: AI 自助会话成本 | B16: =B6*'1-输入参数'!$C$34 | C16: =C6*'1-输入参数'!$C$34 | D16: =D6*'1-输入参数'!$C$34 | E16: AI 会话量 × 单次 AI 成本
A17: AI 平台订阅/摊销 | B17: ='1-输入参数'!$C$35 | C17: ='1-输入参数'!$C$35 | D17: ='1-输入参数'!$C$35
A18: AI 训练师人力成本 | B18: ='1-输入参数'!$C$37*'1-输入参数'!$C$38*12 | C18: ='1-输入参数'!$C$37*'1-输入参数'!$C$38*12 | D18: ='1-输入参数'!$C$37*'1-输入参数'!$C$38*12
A19: 年度模型维护/迭代 | B19: ='1-输入参数'!$C$39 | C19: ='1-输入参数'!$C$39 | D19: ='1-输入参数'!$C$39
A20: AI 总成本 | B20: =B16+B17+B18+B19 | C20: =C16+C17+C18+C19 | D20: =D16+D17+D18+D19 | E20: AI 相关全部开销
A21: 改造后总成本 | B21: =B12+B14+B15+B20 | C21: =C12+C14+C15+C20 | D21: =D12+D14+D15+D20 | E21: 人工 + AI
A22: 现状总成本（基线） | B22: ='2-现状基线'!$C$9 | C22: ='2-现状基线'!$C$9 | D22: ='2-现状基线'!$C$9 | E22: 对照
A23: 年度节省 | B23: =B22-B21 | C23: =C22-C21 | D23: =D22-D21 | E23: 正数 = 降本，负数 = 增本
A24: 降本率 | B24: =B23/B22 | C24: =C23/C22 | D24: =D23/D22
A25: 新单次会话成本 | B25: =B21/B4 | C25: =C21/C4 | D25: =D21/D4
A26: 原单次会话成本 | B26: ='2-现状基线'!$C$10 | C26: ='2-现状基线'!$C$10 | D26: ='2-现状基线'!$C$10
A27: 单次会话成本降幅 | B27: =(B26-B25)/B26 | C27: =(C26-C25)/C26 | D27: =(D26-D25)/D26 | E27: 越大越好
A28: 预计 FCR（改造后） | B28: ='1-输入参数'!$C$18+'1-输入参数'!$C$32 | C28: ='1-输入参数'!$C$18+'1-输入参数'!$C$32 | D28: ='1-输入参数'!$C$18+'1-输入参数'!$C$32
A29: 质检覆盖率 | B29: ='1-输入参数'!$C$30 | C29: ='1-输入参数'!$C$30 | D29: ='1-输入参数'!$C$30
A30: CSAT（估算） | B30: ='1-输入参数'!$C$20+'1-输入参数'!$C$42*(1/3) | C30: ='1-输入参数'!$C$20+'1-输入参数'!$C$42*(2/3) | D30: ='1-输入参数'!$C$20+'1-输入参数'!$C$42*(3/3) | E30: 线性爬升

Sheet 4-分场景收益
A1: 4. 分场景收益明细（Y3 成熟期口径）
A3: 场景 | B3: 覆盖比例 | C3: 单位成本降幅 | D3: 年节省(元) | E3: 上线周期(月) | F3: 实施难度 | G3: 说明
A4: 智能质检全检 | B4: ='1-输入参数'!$C$30 | C4: ='1-输入参数'!$C$31 | D4: ='2-现状基线'!$C$7*'1-输入参数'!$C$31 | E4: 1 | F4: 低 | G4: 最快见效，建议首选
A5: 坐席 Copilot（话术+检索+填单） | B5: ='1-输入参数'!$C$27 | C5: =('1-输入参数'!$C$16*'1-输入参数'!$C$28+'1-输入参数'!$C$17*'1-输入参数'!$C$29)/('1-输入参数'!$C$16+'1-输入参数'!$C$17) | D5: ='2-现状基线'!$C$6*'1-输入参数'!$C$27*(('1-输入参数'!$C$16*'1-输入参数'!$C$28+'1-输入参数'!$C$17*'1-输入参数'!$C$29)/('1-输入参数'!$C$16+'1-输入参数'!$C$17)) | E5: 3 | F5: 中 | G5: AHT/ACW 压缩，坐席减员或承接更多量
A6: RAG 智能自助（高频FAQ/查单/政策） | B6: ='1-输入参数'!$C$24-'1-输入参数'!$C$15 | C6: =1-'1-输入参数'!$C$34/'2-现状基线'!$C$10 | D6: ='2-现状基线'!$C$4*('1-输入参数'!$C$24-'1-输入参数'!$C$15)*('2-现状基线'!$C$10-'1-输入参数'!$C$34) | E6: 3 | F6: 中 | G6: 把简单咨询从人工转到 AI
A7: 会话摘要 + 工单自动生成 | B7: ='1-输入参数'!$C$27 | C7: ='1-输入参数'!$C$17*'1-输入参数'!$C$29/('1-输入参数'!$C$16+'1-输入参数'!$C$17) | D7: ='2-现状基线'!$C$6*'1-输入参数'!$C$27*('1-输入参数'!$C$17*'1-输入参数'!$C$29/('1-输入参数'!$C$16+'1-输入参数'!$C$17)) | E7: 2 | F7: 低 | G7: Copilot 的子项，已含在 Copilot 内，此处仅单独拆解参考
A8: 智能外呼/满意度回访 | B8: 0.8 | C8: 0.7 | D8: ='2-现状基线'!$C$6*0.05*0.80*0.70 | E8: 2 | F8: 低 | G8: 按坐席 5% 从事外呼估算
A9: 全自动 Agent 售后（调 API 闭环） | B9: 0.3 | C9: 0.6 | D9: ='2-现状基线'!$C$4*0.30*('2-现状基线'!$C$10-'1-输入参数'!$C$34)*0.6 | E9: 6 | F9: 高 | G9: 需打通订单/支付/库存 API，第二期做
A10: 培训/陪练/知识沉淀（内部降本） | B10: 1 | C10: 0.3 | D10: =('2-现状基线'!$C$8*0.2)*0.30 | E10: 3 | F10: 低 | G10: 缩短新人爬坡+节省培训人力
A11: 合计（估算，含重叠，见说明） | D11: =SUM(D4:D10) | G11: 此处为简单求和，Copilot 与'摘要'存在口径重叠，真实整合后应以 Sheet3 为准。

Sheet 5-三年现金流ROI
A1: 5. 三年现金流 / NPV / IRR / 回收期
A3: 项目 | B3: Y0 | C3: Y1 | D3: Y2 | E3: Y3 | F3: 说明
A4: 一次性投入（CapEx） | B4: =-'1-输入参数'!$C$36 | C4: 0 | D4: 0 | E4: 0 | F4: 第 0 年项目投入
A5: 年度节省（OpEx 减少） | B5: 0 | C5: ='3-AI改造后测算'!B23 | D5: ='3-AI改造后测算'!C23 | E5: ='3-AI改造后测算'!D23 | F5: 取自 Sheet3
A6: 软性收益估算（CSAT） | B6: 0 | C6: ='1-输入参数'!$C$41*'1-输入参数'!$C$42*100*(1/3) | D6: ='1-输入参数'!$C$41*'1-输入参数'!$C$42*100*(2/3) | E6: ='1-输入参数'!$C$41*'1-输入参数'!$C$42*100*(3/3) | F6: 可选，含义大CSAT不折现时置零
A7: 净现金流 | B7: =B4+B5+B6 | C7: =C4+C5+C6 | D7: =D4+D5+D6 | E7: =E4+E5+E6 | F7: 一次性+节省+软性
A8: 累计净现金流 | B8: =B7 | C8: =B8+C7 | D8: =C8+D7 | E8: =D8+E7 | F8: 首次转正年 = 回收期
A9: 折现净现金流 | B9: =B7/(1+'1-输入参数'!$C$44)^0 | C9: =C7/(1+'1-输入参数'!$C$44)^1 | D9: =D7/(1+'1-输入参数'!$C$44)^2 | E9: =E7/(1+'1-输入参数'!$C$44)^3 | F9: 按 WACC 折现到 Y0
A10: 累计折现净现金流 | B10: =B9 | C10: =B10+C9 | D10: =C10+D9 | E10: =D10+E9 | F10: Y3 累计值 即 NPV（Y0→Y3）
A12: 关键财务指标
A13: NPV（净现值） | B13: =E10 | F13: 越大越好；>0 项目就值得做
A14: IRR（内部收益率） | B14: =IFERROR(IRR(B7:E7),"需调整输入") | F14: 行业经验 AI 项目 IRR > 30% 算优秀
A15: 投资回收期（年，静态） | B15: =IFERROR(MATCH(TRUE,INDEX(B8:E8>0,0),0)-1,"超3年") | F15: 静态回收期，不折现
A16: 三年总节省（不含一次性） | B16: =SUM(C5:E5)+SUM(C6:E6)
A17: 三年 ROI | B17: =(SUM(C5:E5)+SUM(C6:E6)+B4)/(-B4) | F17: （总收益 - 投入）/ 投入

Sheet 6-敏感性分析
A1: 6. 敏感性分析：AI 承接率 × 单次 AI 成本 → Y3 年度节省
A3: AI 承接率 Y3 ↓ / 单次AI成本 → | B3: 0.1 | C3: 0.2 | D3: 0.3 | E3: 0.4 | F3: 0.5 | G3: 0.7 | H3: 1
A4: 0.3 | B4: =('2-现状基线'!$C$9)-(('2-现状基线'!$C$4*(1-0.3)*('1-输入参数'!$C$16*(1-'1-输入参数'!$C$27*'1-输入参数'!$C$28)+'1-输入参数'!$C$17*(1-'1-输入参数'!$C$27*'1-输入参数'!$C$29)))/60/('1-输入参数'!$C$8*12))*'1-输入参数'!$C$10*12-('1-输入参数'!$C$7*(1-'1-输入参数'!$C$31)*'1-输入参数'!$C$11*12)-('2-现状基线'!$C$8*(('2-现状基线'!$C$4*(1-0.3)*('1-输入参数'!$C$16*(1-'1-输入参数'!$C$27*'1-输入参数'!$C$28)+'1-输入参数'!$C$17*(1-'1-输入参数'!$C$27*'1-输入参数'!$C$29)))/60/('1-输入参数'!$C$8*12))/'1-输入参数'!$C$6)-('2-现状基线'!$C$4*0.3*0.1)-'1-输入参数'!$C$35-'1-输入参数'!$C$37*'1-输入参数'!$C$38*12-'1-输入参数'!$C$39 | C4: =('2-现状基线'!$C$9)-(('2-现状基线'!$C$4*(1-0.3)*('1-输入参数'!$C$16*(1-'1-输入参数'!$C$27*'1-输入参数'!$C$28)+'1-输入参数'!$C$17*(1-'1-输入参数'!$C$27*'1-输入参数'!$C$29)))/60/('1-输入参数'!$C$8*12))*'1-输入参数'!$C$10*12-('1-输入参数'!$C$7*(1-'1-输入参数'!$C$31)*'1-输入参数'!$C$11*12)-('2-现状基线'!$C$8*(('2-现状基线'!$C$4*(1-0.3)*('1-输入参数'!$C$16*(1-'1-输入参数'!$C$27*'1-输入参数'!$C$28)+'1-输入参数'!$C$17*(1-'1-输入参数'!$C$27*'1-输入参数'!$C$29)))/60/('1-输入参数'!$C$8*12))/'1-输入参数'!$C$6)-('2-现状基线'!$C$4*0.3*0.2)-'1-输入参数'!$C$35-'1-输入参数'!$C$37*'1-输入参数'!$C$38*12-'1-输入参数'!$C$39 | D4: =('2-现状基线'!$C$9)-(('2-现状基线'!$C$4*(1-0.3)*('1-输入参数'!$C$16*(1-'1-输入参数'!$C$27*'1-输入参数'!$C$28)+'1-输入参数'!$C$17*(1-'1-输入参数'!$C$27*'1-输入参数'!$C$29)))/60/('1-输入参数'!$C$8*12))*'1-输入参数'!$C$10*12-('1-输入参数'!$C$7*(1-'1-输入参数'!$C$31)*'1-输入参数'!$C$11*12)-('2-现状基线'!$C$8*(('2-现状基线'!$C$4*(1-0.3)*('1-输入参数'!$C$16*(1-'1-输入参数'!$C$27*'1-输入参数'!$C$28)+'1-输入参数'!$C$17*(1-'1-输入参数'!$C$27*'1-输入参数'!$C$29)))/60/('1-输入参数'!$C$8*12))/'1-输入参数'!$C$6)-('2-现状基线'!$C$4*0.3*0.3)-'1-输入参数'!$C$35-'1-输入参数'!$C$37*'1-输入参数'!$C$38*12-'1-输入参数'!$C$39 | E4: =('2-现状基线'!$C$9)-(('2-现状基线'!$C$4*(1-0.3)*('1-输入参数'!$C$16*(1-'1-输入参数'!$C$27*'1-输入参数'!$C$28)+'1-输入参数'!$C$17*(1-'1-输入参数'!$C$27*'1-输入参数'!$C$29)))/60/('1-输入参数'!$C$8*12))*'1-输入参数'!$C$10*12-('1-输入参数'!$C$7*(1-'1-输入参数'!$C$31)*'1-输入参数'!$C$11*12)-('2-现状基线'!$C$8*(('2-现状基线'!$C$4*(1-0.3)*('1-输入参数'!$C$16*(1-'1-输入参数'!$C$27*'1-输入参数'!$C$28)+'1-输入参数'!$C$17*(1-'1-输入参数'!$C$27*'1-输入参数'!$C$29)))/60/('1-输入参数'!$C$8*12))/'1-输入参数'!$C$6)-('2-现状基线'!$C$4*0.3*0.4)-'1-输入参数'!$C$35-'1-输入参数'!$C$37*'1-输入参数'!$C$38*12-'1-输入参数'!$C$39 | F4: =('2-现状基线'!$C$9)-(('2-现状基线'!$C$4*(1-0.3)*('1-输入参数'!$C$16*(1-'1-输入参数'!$C$27*'1-输入参数'!$C$28)+'1-输入参数'!$C$17*(1-'1-输入参数'!$C$27*'1-输入参数'!$C$29)))/60/('1-输入参数'!$C$8*12))*'1-输入参数'!$C$10*12-('1-输入参数'!$C$7*(1-'1-输入参数'!$C$31)*'1-输入参数'!$C$11*12)-('2-现状基线'!$C$8*(('2-现状基线'!$C$4*(1-0.3)*('1-输入参数'!$C$16*(1-'1-输入参数'!$C$27*'1-输入参数'!$C$28)+'1-输入参数'!$C$17*(1-'1-输入参数'!$C$27*'1-输入参数'!$C$29)))/60/('1-输入参数'!$C$8*12))/'1-输入参数'!$C$6)-('2-现状基线'!$C$4*0.3*0.5)-'1-输入参数'!$C$35-'1-输入参数'!$C$37*'1-输入参数'!$C$38*12-'1-输入参数'!$C$39 | G4: =('2-现状基线'!$C$9)-(('2-现状基线'!$C$4*(1-0.3)*('1-输入参数'!$C$16*(1-'1-输入参数'!$C$27*'1-输入参数'!$C$28)+'1-输入参数'!$C$17*(1-'1-输入参数'!$C$27*'1-输入参数'!$C$29)))/60/('1-输入参数'!$C$8*12))*'1-输入参数'!$C$10*12-('1-输入参数'!$C$7*(1-'1-输入参数'!$C$31)*'1-输入参数'!$C$11*12)-('2-现状基线'!$C$8*(('2-现状基线'!$C$4*(1-0.3)*('1-输入参数'!$C$16*(1-'1-输入参数'!$C$27*'1-输入参数'!$C$28)+'1-输入参数'!$C$17*(1-'1-输入参数'!$C$27*'1-输入参数'!$C$29)))/60/('1-输入参数'!$C$8*12))/'1-输入参数'!$C$6)-('2-现状基线'!$C$4*0.3*0.7)-'1-输入参数'!$C$35-'1-输入参数'!$C$37*'1-输入参数'!$C$38*12-'1-输入参数'!$C$39 | H4: =('2-现状基线'!$C$9)-(('2-现状基线'!$C$4*(1-0.3)*('1-输入参数'!$C$16*(1-'1-输入参数'!$C$27*'1-输入参数'!$C$28)+'1-输入参数'!$C$17*(1-'1-输入参数'!$C$27*'1-输入参数'!$C$29)))/60/('1-输入参数'!$C$8*12))*'1-输入参数'!$C$10*12-('1-输入参数'!$C$7*(1-'1-输入参数'!$C$31)*'1-输入参数'!$C$11*12)-('2-现状基线'!$C$8*(('2-现状基线'!$C$4*(1-0.3)*('1-输入参数'!$C$16*(1-'1-输入参数'!$C$27*'1-输入参数'!$C$28)+'1-输入参数'!$C$17*(1-'1-输入参数'!$C$27*'1-输入参数'!$C$29)))/60/('1-输入参数'!$C$8*12))/'1-输入参数'!$C$6)-('2-现状基线'!$C$4*0.3*1.0)-'1-输入参数'!$C$35-'1-输入参数'!$C$37*'1-输入参数'!$C$38*12-'1-输入参数'!$C$39
A5: 0.4 | B5: =('2-现状基线'!$C$9)-(('2-现状基线'!$C$4*(1-0.4)*('1-输入参数'!$C$16*(1-'1-输入参数'!$C$27*'1-输入参数'!$C$28)+'1-输入参数'!$C$17*(1-'1-输入参数'!$C$27*'1-输入参数'!$C$29)))/60/('1-输入参数'!$C$8*12))*'1-输入参数'!$C$10*12-('1-输入参数'!$C$7*(1-'1-输入参数'!$C$31)*'1-输入参数'!$C$11*12)-('2-现状基线'!$C$8*(('2-现状基线'!$C$4*(1-0.4)*('1-输入参数'!$C$16*(1-'1-输入参数'!$C$27*'1-输入参数'!$C$28)+'1-输入参数'!$C$17*(1-'1-输入参数'!$C$27*'1-输入参数'!$C$29)))/60/('1-输入参数'!$C$8*12))/'1-输入参数'!$C$6)-('2-现状基线'!$C$4*0.4*0.1)-'1-输入参数'!$C$35-'1-输入参数'!$C$37*'1-输入参数'!$C$38*12-'1-输入参数'!$C$39 | C5: =('2-现状基线'!$C$9)-(('2-现状基线'!$C$4*(1-0.4)*('1-输入参数'!$C$16*(1-'1-输入参数'!$C$27*'1-输入参数'!$C$28)+'1-输入参数'!$C$17*(1-'1-输入参数'!$C$27*'1-输入参数'!$C$29)))/60/('1-输入参数'!$C$8*12))*'1-输入参数'!$C$10*12-('1-输入参数'!$C$7*(1-'1-输入参数'!$C$31)*'1-输入参数'!$C$11*12)-('2-现状基线'!$C$8*(('2-现状基线'!$C$4*(1-0.4)*('1-输入参数'!$C$16*(1-'1-输入参数'!$C$27*'1-输入参数'!$C$28)+'1-输入参数'!$C$17*(1-'1-输入参数'!$C$27*'1-输入参数'!$C$29)))/60/('1-输入参数'!$C$8*12))/'1-输入参数'!$C$6)-('2-现状基线'!$C$4*0.4*0.2)-'1-输入参数'!$C$35-'1-输入参数'!$C$37*'1-输入参数'!$C$38*12-'1-输入参数'!$C$39 | D5: =('2-现状基线'!$C$9)-(('2-现状基线'!$C$4*(1-0.4)*('1-输入参数'!$C$16*(1-'1-输入参数'!$C$27*'1-输入参数'!$C$28)+'1-输入参数'!$C$17*(1-'1-输入参数'!$C$27*'1-输入参数'!$C$29)))/60/('1-输入参数'!$C$8*12))*'1-输入参数'!$C$10*12-('1-输入参数'!$C$7*(1-'1-输入参数'!$C$31)*'1-输入参数'!$C$11*12)-('2-现状基线'!$C$8*(('2-现状基线'!$C$4*(1-0.4)*('1-输入参数'!$C$16*(1-'1-输入参数'!$C$27*'1-输入参数'!$C$28)+'1-输入参数'!$C$17*(1-'1-输入参数'!$C$27*'1-输入参数'!$C$29)))/60/('1-输入参数'!$C$8*12))/'1-输入参数'!$C$6)-('2-现状基线'!$C$4*0.4*0.3)-'1-输入参数'!$C$35-'1-输入参数'!$C$37*'1-输入参数'!$C$38*12-'1-输入参数'!$C$39 | E5: =('2-现状基线'!$C$9)-(('2-现状基线'!$C$4*(1-0.4)*('1-输入参数'!$C$16*(1-'1-输入参数'!$C$27*'1-输入参数'!$C$28)+'1-输入参数'!$C$17*(1-'1-输入参数'!$C$27*'1-输入参数'!$C$29)))/60/('1-输入参数'!$C$8*12))*'1-输入参数'!$C$10*12-('1-输入参数'!$C$7*(1-'1-输入参数'!$C$31)*'1-输入参数'!$C$11*12)-('2-现状基线'!$C$8*(('2-现状基线'!$C$4*(1-0.4)*('1-输入参数'!$C$16*(1-'1-输入参数'!$C$27*'1-输入参数'!$C$28)+'1-输入参数'!$C$17*(1-'1-输入参数'!$C$27*'1-输入参数'!$C$29)))/60/('1-输入参数'!$C$8*12))/'1-输入参数'!$C$6)-('2-现状基线'!$C$4*0.4*0.4)-'1-输入参数'!$C$35-'1-输入参数'!$C$37*'1-输入参数'!$C$38*12-'1-输入参数'!$C$39 | F5: =('2-现状基线'!$C$9)-(('2-现状基线'!$C$4*(1-0.4)*('1-输入参数'!$C$16*(1-'1-输入参数'!$C$27*'1-输入参数'!$C$28)+'1-输入参数'!$C$17*(1-'1-输入参数'!$C$27*'1-输入参数'!$C$29)))/60/('1-输入参数'!$C$8*12))*'1-输入参数'!$C$10*12-('1-输入参数'!$C$7*(1-'1-输入参数'!$C$31)*'1-输入参数'!$C$11*12)-('2-现状基线'!$C$8*(('2-现状基线'!$C$4*(1-0.4)*('1-输入参数'!$C$16*(1-'1-输入参数'!$C$27*'1-输入参数'!$C$28)+'1-输入参数'!$C$17*(1-'1-输入参数'!$C$27*'1-输入参数'!$C$29)))/60/('1-输入参数'!$C$8*12))/'1-输入参数'!$C$6)-('2-现状基线'!$C$4*0.4*0.5)-'1-输入参数'!$C$35-'1-输入参数'!$C$37*'1-输入参数'!$C$38*12-'1-输入参数'!$C$39 | G5: =('2-现状基线'!$C$9)-(('2-现状基线'!$C$4*(1-0.4)*('1-输入参数'!$C$16*(1-'1-输入参数'!$C$27*'1-输入参数'!$C$28)+'1-输入参数'!$C$17*(1-'1-输入参数'!$C$27*'1-输入参数'!$C$29)))/60/('1-输入参数'!$C$8*12))*'1-输入参数'!$C$10*12-('1-输入参数'!$C$7*(1-'1-输入参数'!$C$31)*'1-输入参数'!$C$11*12)-('2-现状基线'!$C$8*(('2-现状基线'!$C$4*(1-0.4)*('1-输入参数'!$C$16*(1-'1-输入参数'!$C$27*'1-输入参数'!$C$28)+'1-输入参数'!$C$17*(1-'1-输入参数'!$C$27*'1-输入参数'!$C$29)))/60/('1-输入参数'!$C$8*12))/'1-输入参数'!$C$6)-('2-现状基线'!$C$4*0.4*0.7)-'1-输入参数'!$C$35-'1-输入参数'!$C$37*'1-输入参数'!$C$38*12-'1-输入参数'!$C$39 | H5: =('2-现状基线'!$C$9)-(('2-现状基线'!$C$4*(1-0.4)*('1-输入参数'!$C$16*(1-'1-输入参数'!$C$27*'1-输入参数'!$C$28)+'1-输入参数'!$C$17*(1-'1-输入参数'!$C$27*'1-输入参数'!$C$29)))/60/('1-输入参数'!$C$8*12))*'1-输入参数'!$C$10*12-('1-输入参数'!$C$7*(1-'1-输入参数'!$C$31)*'1-输入参数'!$C$11*12)-('2-现状基线'!$C$8*(('2-现状基线'!$C$4*(1-0.4)*('1-输入参数'!$C$16*(1-'1-输入参数'!$C$27*'1-输入参数'!$C$28)+'1-输入参数'!$C$17*(1-'1-输入参数'!$C$27*'1-输入参数'!$C$29)))/60/('1-输入参数'!$C$8*12))/'1-输入参数'!$C$6)-('2-现状基线'!$C$4*0.4*1.0)-'1-输入参数'!$C$35-'1-输入参数'!$C$37*'1-输入参数'!$C$38*12-'1-输入参数'!$C$39
A6: 0.5 | B6: =('2-现状基线'!$C$9)-(('2-现状基线'!$C$4*(1-0.5)*('1-输入参数'!$C$16*(1-'1-输入参数'!$C$27*'1-输入参数'!$C$28)+'1-输入参数'!$C$17*(1-'1-输入参数'!$C$27*'1-输入参数'!$C$29)))/60/('1-输入参数'!$C$8*12))*'1-输入参数'!$C$10*12-('1-输入参数'!$C$7*(1-'1-输入参数'!$C$31)*'1-输入参数'!$C$11*12)-('2-现状基线'!$C$8*(('2-现状基线'!$C$4*(1-0.5)*('1-输入参数'!$C$16*(1-'1-输入参数'!$C$27*'1-输入参数'!$C$28)+'1-输入参数'!$C$17*(1-'1-输入参数'!$C$27*'1-输入参数'!$C$29)))/60/('1-输入参数'!$C$8*12))/'1-输入参数'!$C$6)-('2-现状基线'!$C$4*0.5*0.1)-'1-输入参数'!$C$35-'1-输入参数'!$C$37*'1-输入参数'!$C$38*12-'1-输入参数'!$C$39 | C6: =('2-现状基线'!$C$9)-(('2-现状基线'!$C$4*(1-0.5)*('1-输入参数'!$C$16*(1-'1-输入参数'!$C$27*'1-输入参数'!$C$28)+'1-输入参数'!$C$17*(1-'1-输入参数'!$C$27*'1-输入参数'!$C$29)))/60/('1-输入参数'!$C$8*12))*'1-输入参数'!$C$10*12-('1-输入参数'!$C$7*(1-'1-输入参数'!$C$31)*'1-输入参数'!$C$11*12)-('2-现状基线'!$C$8*(('2-现状基线'!$C$4*(1-0.5)*('1-输入参数'!$C$16*(1-'1-输入参数'!$C$27*'1-输入参数'!$C$28)+'1-输入参数'!$C$17*(1-'1-输入参数'!$C$27*'1-输入参数'!$C$29)))/60/('1-输入参数'!$C$8*12))/'1-输入参数'!$C$6)-('2-现状基线'!$C$4*0.5*0.2)-'1-输入参数'!$C$35-'1-输入参数'!$C$37*'1-输入参数'!$C$38*12-'1-输入参数'!$C$39 | D6: =('2-现状基线'!$C$9)-(('2-现状基线'!$C$4*(1-0.5)*('1-输入参数'!$C$16*(1-'1-输入参数'!$C$27*'1-输入参数'!$C$28)+'1-输入参数'!$C$17*(1-'1-输入参数'!$C$27*'1-输入参数'!$C$29)))/60/('1-输入参数'!$C$8*12))*'1-输入参数'!$C$10*12-('1-输入参数'!$C$7*(1-'1-输入参数'!$C$31)*'1-输入参数'!$C$11*12)-('2-现状基线'!$C$8*(('2-现状基线'!$C$4*(1-0.5)*('1-输入参数'!$C$16*(1-'1-输入参数'!$C$27*'1-输入参数'!$C$28)+'1-输入参数'!$C$17*(1-'1-输入参数'!$C$27*'1-输入参数'!$C$29)))/60/('1-输入参数'!$C$8*12))/'1-输入参数'!$C$6)-('2-现状基线'!$C$4*0.5*0.3)-'1-输入参数'!$C$35-'1-输入参数'!$C$37*'1-输入参数'!$C$38*12-'1-输入参数'!$C$39 | E6: =('2-现状基线'!$C$9)-(('2-现状基线'!$C$4*(1-0.5)*('1-输入参数'!$C$16*(1-'1-输入参数'!$C$27*'1-输入参数'!$C$28)+'1-输入参数'!$C$17*(1-'1-输入参数'!$C$27*'1-输入参数'!$C$29)))/60/('1-输入参数'!$C$8*12))*'1-输入参数'!$C$10*12-('1-输入参数'!$C$7*(1-'1-输入参数'!$C$31)*'1-输入参数'!$C$11*12)-('2-现状基线'!$C$8*(('2-现状基线'!$C$4*(1-0.5)*('1-输入参数'!$C$16*(1-'1-输入参数'!$C$27*'1-输入参数'!$C$28)+'1-输入参数'!$C$17*(1-'1-输入参数'!$C$27*'1-输入参数'!$C$29)))/60/('1-输入参数'!$C$8*12))/'1-输入参数'!$C$6)-('2-现状基线'!$C$4*0.5*0.4)-'1-输入参数'!$C$35-'1-输入参数'!$C$37*'1-输入参数'!$C$38*12-'1-输入参数'!$C$39 | F6: =('2-现状基线'!$C$9)-(('2-现状基线'!$C$4*(1-0.5)*('1-输入参数'!$C$16*(1-'1-输入参数'!$C$27*'1-输入参数'!$C$28)+'1-输入参数'!$C$17*(1-'1-输入参数'!$C$27*'1-输入参数'!$C$29)))/60/('1-输入参数'!$C$8*12))*'1-输入参数'!$C$10*12-('1-输入参数'!$C$7*(1-'1-输入参数'!$C$31)*'1-输入参数'!$C$11*12)-('2-现状基线'!$C$8*(('2-现状基线'!$C$4*(1-0.5)*('1-输入参数'!$C$16*(1-'1-输入参数'!$C$27*'1-输入参数'!$C$28)+'1-输入参数'!$C$17*(1-'1-输入参数'!$C$27*'1-输入参数'!$C$29)))/60/('1-输入参数'!$C$8*12))/'1-输入参数'!$C$6)-('2-现状基线'!$C$4*0.5*0.5)-'1-输入参数'!$C$35-'1-输入参数'!$C$37*'1-输入参数'!$C$38*12-'1-输入参数'!$C$39 | G6: =('2-现状基线'!$C$9)-(('2-现状基线'!$C$4*(1-0.5)*('1-输入参数'!$C$16*(1-'1-输入参数'!$C$27*'1-输入参数'!$C$28)+'1-输入参数'!$C$17*(1-'1-输入参数'!$C$27*'1-输入参数'!$C$29)))/60/('1-输入参数'!$C$8*12))*'1-输入参数'!$C$10*12-('1-输入参数'!$C$7*(1-'1-输入参数'!$C$31)*'1-输入参数'!$C$11*12)-('2-现状基线'!$C$8*(('2-现状基线'!$C$4*(1-0.5)*('1-输入参数'!$C$16*(1-'1-输入参数'!$C$27*'1-输入参数'!$C$28)+'1-输入参数'!$C$17*(1-'1-输入参数'!$C$27*'1-输入参数'!$C$29)))/60/('1-输入参数'!$C$8*12))/'1-输入参数'!$C$6)-('2-现状基线'!$C$4*0.5*0.7)-'1-输入参数'!$C$35-'1-输入参数'!$C$37*'1-输入参数'!$C$38*12-'1-输入参数'!$C$39 | H6: =('2-现状基线'!$C$9)-(('2-现状基线'!$C$4*(1-0.5)*('1-输入参数'!$C$16*(1-'1-输入参数'!$C$27*'1-输入参数'!$C$28)+'1-输入参数'!$C$17*(1-'1-输入参数'!$C$27*'1-输入参数'!$C$29)))/60/('1-输入参数'!$C$8*12))*'1-输入参数'!$C$10*12-('1-输入参数'!$C$7*(1-'1-输入参数'!$C$31)*'1-输入参数'!$C$11*12)-('2-现状基线'!$C$8*(('2-现状基线'!$C$4*(1-0.5)*('1-输入参数'!$C$16*(1-'1-输入参数'!$C$27*'1-输入参数'!$C$28)+'1-输入参数'!$C$17*(1-'1-输入参数'!$C$27*'1-输入参数'!$C$29)))/60/('1-输入参数'!$C$8*12))/'1-输入参数'!$C$6)-('2-现状基线'!$C$4*0.5*1.0)-'1-输入参数'!$C$35-'1-输入参数'!$C$37*'1-输入参数'!$C$38*12-'1-输入参数'!$C$39
A7: 0.6 | B7: =('2-现状基线'!$C$9)-(('2-现状基线'!$C$4*(1-0.6)*('1-输入参数'!$C$16*(1-'1-输入参数'!$C$27*'1-输入参数'!$C$28)+'1-输入参数'!$C$17*(1-'1-输入参数'!$C$27*'1-输入参数'!$C$29)))/60/('1-输入参数'!$C$8*12))*'1-输入参数'!$C$10*12-('1-输入参数'!$C$7*(1-'1-输入参数'!$C$31)*'1-输入参数'!$C$11*12)-('2-现状基线'!$C$8*(('2-现状基线'!$C$4*(1-0.6)*('1-输入参数'!$C$16*(1-'1-输入参数'!$C$27*'1-输入参数'!$C$28)+'1-输入参数'!$C$17*(1-'1-输入参数'!$C$27*'1-输入参数'!$C$29)))/60/('1-输入参数'!$C$8*12))/'1-输入参数'!$C$6)-('2-现状基线'!$C$4*0.6*0.1)-'1-输入参数'!$C$35-'1-输入参数'!$C$37*'1-输入参数'!$C$38*12-'1-输入参数'!$C$39 | C7: =('2-现状基线'!$C$9)-(('2-现状基线'!$C$4*(1-0.6)*('1-输入参数'!$C$16*(1-'1-输入参数'!$C$27*'1-输入参数'!$C$28)+'1-输入参数'!$C$17*(1-'1-输入参数'!$C$27*'1-输入参数'!$C$29)))/60/('1-输入参数'!$C$8*12))*'1-输入参数'!$C$10*12-('1-输入参数'!$C$7*(1-'1-输入参数'!$C$31)*'1-输入参数'!$C$11*12)-('2-现状基线'!$C$8*(('2-现状基线'!$C$4*(1-0.6)*('1-输入参数'!$C$16*(1-'1-输入参数'!$C$27*'1-输入参数'!$C$28)+'1-输入参数'!$C$17*(1-'1-输入参数'!$C$27*'1-输入参数'!$C$29)))/60/('1-输入参数'!$C$8*12))/'1-输入参数'!$C$6)-('2-现状基线'!$C$4*0.6*0.2)-'1-输入参数'!$C$35-'1-输入参数'!$C$37*'1-输入参数'!$C$38*12-'1-输入参数'!$C$39 | D7: =('2-现状基线'!$C$9)-(('2-现状基线'!$C$4*(1-0.6)*('1-输入参数'!$C$16*(1-'1-输入参数'!$C$27*'1-输入参数'!$C$28)+'1-输入参数'!$C$17*(1-'1-输入参数'!$C$27*'1-输入参数'!$C$29)))/60/('1-输入参数'!$C$8*12))*'1-输入参数'!$C$10*12-('1-输入参数'!$C$7*(1-'1-输入参数'!$C$31)*'1-输入参数'!$C$11*12)-('2-现状基线'!$C$8*(('2-现状基线'!$C$4*(1-0.6)*('1-输入参数'!$C$16*(1-'1-输入参数'!$C$27*'1-输入参数'!$C$28)+'1-输入参数'!$C$17*(1-'1-输入参数'!$C$27*'1-输入参数'!$C$29)))/60/('1-输入参数'!$C$8*12))/'1-输入参数'!$C$6)-('2-现状基线'!$C$4*0.6*0.3)-'1-输入参数'!$C$35-'1-输入参数'!$C$37*'1-输入参数'!$C$38*12-'1-输入参数'!$C$39 | E7: =('2-现状基线'!$C$9)-(('2-现状基线'!$C$4*(1-0.6)*('1-输入参数'!$C$16*(1-'1-输入参数'!$C$27*'1-输入参数'!$C$28)+'1-输入参数'!$C$17*(1-'1-输入参数'!$C$27*'1-输入参数'!$C$29)))/60/('1-输入参数'!$C$8*12))*'1-输入参数'!$C$10*12-('1-输入参数'!$C$7*(1-'1-输入参数'!$C$31)*'1-输入参数'!$C$11*12)-('2-现状基线'!$C$8*(('2-现状基线'!$C$4*(1-0.6)*('1-输入参数'!$C$16*(1-'1-输入参数'!$C$27*'1-输入参数'!$C$28)+'1-输入参数'!$C$17*(1-'1-输入参数'!$C$27*'1-输入参数'!$C$29)))/60/('1-输入参数'!$C$8*12))/'1-输入参数'!$C$6)-('2-现状基线'!$C$4*0.6*0.4)-'1-输入参数'!$C$35-'1-输入参数'!$C$37*'1-输入参数'!$C$38*12-'1-输入参数'!$C$39 | F7: =('2-现状基线'!$C$9)-(('2-现状基线'!$C$4*(1-0.6)*('1-输入参数'!$C$16*(1-'1-输入参数'!$C$27*'1-输入参数'!$C$28)+'1-输入参数'!$C$17*(1-'1-输入参数'!$C$27*'1-输入参数'!$C$29)))/60/('1-输入参数'!$C$8*12))*'1-输入参数'!$C$10*12-('1-输入参数'!$C$7*(1-'1-输入参数'!$C$31)*'1-输入参数'!$C$11*12)-('2-现状基线'!$C$8*(('2-现状基线'!$C$4*(1-0.6)*('1-输入参数'!$C$16*(1-'1-输入参数'!$C$27*'1-输入参数'!$C$28)+'1-输入参数'!$C$17*(1-'1-输入参数'!$C$27*'1-输入参数'!$C$29)))/60/('1-输入参数'!$C$8*12))/'1-输入参数'!$C$6)-('2-现状基线'!$C$4*0.6*0.5)-'1-输入参数'!$C$35-'1-输入参数'!$C$37*'1-输入参数'!$C$38*12-'1-输入参数'!$C$39 | G7: =('2-现状基线'!$C$9)-(('2-现状基线'!$C$4*(1-0.6)*('1-输入参数'!$C$16*(1-'1-输入参数'!$C$27*'1-输入参数'!$C$28)+'1-输入参数'!$C$17*(1-'1-输入参数'!$C$27*'1-输入参数'!$C$29)))/60/('1-输入参数'!$C$8*12))*'1-输入参数'!$C$10*12-('1-输入参数'!$C$7*(1-'1-输入参数'!$C$31)*'1-输入参数'!$C$11*12)-('2-现状基线'!$C$8*(('2-现状基线'!$C$4*(1-0.6)*('1-输入参数'!$C$16*(1-'1-输入参数'!$C$27*'1-输入参数'!$C$28)+'1-输入参数'!$C$17*(1-'1-输入参数'!$C$27*'1-输入参数'!$C$29)))/60/('1-输入参数'!$C$8*12))/'1-输入参数'!$C$6)-('2-现状基线'!$C$4*0.6*0.7)-'1-输入参数'!$C$35-'1-输入参数'!$C$37*'1-输入参数'!$C$38*12-'1-输入参数'!$C$39 | H7: =('2-现状基线'!$C$9)-(('2-现状基线'!$C$4*(1-0.6)*('1-输入参数'!$C$16*(1-'1-输入参数'!$C$27*'1-输入参数'!$C$28)+'1-输入参数'!$C$17*(1-'1-输入参数'!$C$27*'1-输入参数'!$C$29)))/60/('1-输入参数'!$C$8*12))*'1-输入参数'!$C$10*12-('1-输入参数'!$C$7*(1-'1-输入参数'!$C$31)*'1-输入参数'!$C$11*12)-('2-现状基线'!$C$8*(('2-现状基线'!$C$4*(1-0.6)*('1-输入参数'!$C$16*(1-'1-输入参数'!$C$27*'1-输入参数'!$C$28)+'1-输入参数'!$C$17*(1-'1-输入参数'!$C$27*'1-输入参数'!$C$29)))/60/('1-输入参数'!$C$8*12))/'1-输入参数'!$C$6)-('2-现状基线'!$C$4*0.6*1.0)-'1-输入参数'!$C$35-'1-输入参数'!$C$37*'1-输入参数'!$C$38*12-'1-输入参数'!$C$39
A8: 0.7 | B8: =('2-现状基线'!$C$9)-(('2-现状基线'!$C$4*(1-0.7)*('1-输入参数'!$C$16*(1-'1-输入参数'!$C$27*'1-输入参数'!$C$28)+'1-输入参数'!$C$17*(1-'1-输入参数'!$C$27*'1-输入参数'!$C$29)))/60/('1-输入参数'!$C$8*12))*'1-输入参数'!$C$10*12-('1-输入参数'!$C$7*(1-'1-输入参数'!$C$31)*'1-输入参数'!$C$11*12)-('2-现状基线'!$C$8*(('2-现状基线'!$C$4*(1-0.7)*('1-输入参数'!$C$16*(1-'1-输入参数'!$C$27*'1-输入参数'!$C$28)+'1-输入参数'!$C$17*(1-'1-输入参数'!$C$27*'1-输入参数'!$C$29)))/60/('1-输入参数'!$C$8*12))/'1-输入参数'!$C$6)-('2-现状基线'!$C$4*0.7*0.1)-'1-输入参数'!$C$35-'1-输入参数'!$C$37*'1-输入参数'!$C$38*12-'1-输入参数'!$C$39 | C8: =('2-现状基线'!$C$9)-(('2-现状基线'!$C$4*(1-0.7)*('1-输入参数'!$C$16*(1-'1-输入参数'!$C$27*'1-输入参数'!$C$28)+'1-输入参数'!$C$17*(1-'1-输入参数'!$C$27*'1-输入参数'!$C$29)))/60/('1-输入参数'!$C$8*12))*'1-输入参数'!$C$10*12-('1-输入参数'!$C$7*(1-'1-输入参数'!$C$31)*'1-输入参数'!$C$11*12)-('2-现状基线'!$C$8*(('2-现状基线'!$C$4*(1-0.7)*('1-输入参数'!$C$16*(1-'1-输入参数'!$C$27*'1-输入参数'!$C$28)+'1-输入参数'!$C$17*(1-'1-输入参数'!$C$27*'1-输入参数'!$C$29)))/60/('1-输入参数'!$C$8*12))/'1-输入参数'!$C$6)-('2-现状基线'!$C$4*0.7*0.2)-'1-输入参数'!$C$35-'1-输入参数'!$C$37*'1-输入参数'!$C$38*12-'1-输入参数'!$C$39 | D8: =('2-现状基线'!$C$9)-(('2-现状基线'!$C$4*(1-0.7)*('1-输入参数'!$C$16*(1-'1-输入参数'!$C$27*'1-输入参数'!$C$28)+'1-输入参数'!$C$17*(1-'1-输入参数'!$C$27*'1-输入参数'!$C$29)))/60/('1-输入参数'!$C$8*12))*'1-输入参数'!$C$10*12-('1-输入参数'!$C$7*(1-'1-输入参数'!$C$31)*'1-输入参数'!$C$11*12)-('2-现状基线'!$C$8*(('2-现状基线'!$C$4*(1-0.7)*('1-输入参数'!$C$16*(1-'1-输入参数'!$C$27*'1-输入参数'!$C$28)+'1-输入参数'!$C$17*(1-'1-输入参数'!$C$27*'1-输入参数'!$C$29)))/60/('1-输入参数'!$C$8*12))/'1-输入参数'!$C$6)-('2-现状基线'!$C$4*0.7*0.3)-'1-输入参数'!$C$35-'1-输入参数'!$C$37*'1-输入参数'!$C$38*12-'1-输入参数'!$C$39 | E8: =('2-现状基线'!$C$9)-(('2-现状基线'!$C$4*(1-0.7)*('1-输入参数'!$C$16*(1-'1-输入参数'!$C$27*'1-输入参数'!$C$28)+'1-输入参数'!$C$17*(1-'1-输入参数'!$C$27*'1-输入参数'!$C$29)))/60/('1-输入参数'!$C$8*12))*'1-输入参数'!$C$10*12-('1-输入参数'!$C$7*(1-'1-输入参数'!$C$31)*'1-输入参数'!$C$11*12)-('2-现状基线'!$C$8*(('2-现状基线'!$C$4*(1-0.7)*('1-输入参数'!$C$16*(1-'1-输入参数'!$C$27*'1-输入参数'!$C$28)+'1-输入参数'!$C$17*(1-'1-输入参数'!$C$27*'1-输入参数'!$C$29)))/60/('1-输入参数'!$C$8*12))/'1-输入参数'!$C$6)-('2-现状基线'!$C$4*0.7*0.4)-'1-输入参数'!$C$35-'1-输入参数'!$C$37*'1-输入参数'!$C$38*12-'1-输入参数'!$C$39 | F8: =('2-现状基线'!$C$9)-(('2-现状基线'!$C$4*(1-0.7)*('1-输入参数'!$C$16*(1-'1-输入参数'!$C$27*'1-输入参数'!$C$28)+'1-输入参数'!$C$17*(1-'1-输入参数'!$C$27*'1-输入参数'!$C$29)))/60/('1-输入参数'!$C$8*12))*'1-输入参数'!$C$10*12-('1-输入参数'!$C$7*(1-'1-输入参数'!$C$31)*'1-输入参数'!$C$11*12)-('2-现状基线'!$C$8*(('2-现状基线'!$C$4*(1-0.7)*('1-输入参数'!$C$16*(1-'1-输入参数'!$C$27*'1-输入参数'!$C$28)+'1-输入参数'!$C$17*(1-'1-输入参数'!$C$27*'1-输入参数'!$C$29)))/60/('1-输入参数'!$C$8*12))/'1-输入参数'!$C$6)-('2-现状基线'!$C$4*0.7*0.5)-'1-输入参数'!$C$35-'1-输入参数'!$C$37*'1-输入参数'!$C$38*12-'1-输入参数'!$C$39 | G8: =('2-现状基线'!$C$9)-(('2-现状基线'!$C$4*(1-0.7)*('1-输入参数'!$C$16*(1-'1-输入参数'!$C$27*'1-输入参数'!$C$28)+'1-输入参数'!$C$17*(1-'1-输入参数'!$C$27*'1-输入参数'!$C$29)))/60/('1-输入参数'!$C$8*12))*'1-输入参数'!$C$10*12-('1-输入参数'!$C$7*(1-'1-输入参数'!$C$31)*'1-输入参数'!$C$11*12)-('2-现状基线'!$C$8*(('2-现状基线'!$C$4*(1-0.7)*('1-输入参数'!$C$16*(1-'1-输入参数'!$C$27*'1-输入参数'!$C$28)+'1-输入参数'!$C$17*(1-'1-输入参数'!$C$27*'1-输入参数'!$C$29)))/60/('1-输入参数'!$C$8*12))/'1-输入参数'!$C$6)-('2-现状基线'!$C$4*0.7*0.7)-'1-输入参数'!$C$35-'1-输入参数'!$C$37*'1-输入参数'!$C$38*12-'1-输入参数'!$C$39 | H8: =('2-现状基线'!$C$9)-(('2-现状基线'!$C$4*(1-0.7)*('1-输入参数'!$C$16*(1-'1-输入参数'!$C$27*'1-输入参数'!$C$28)+'1-输入参数'!$C$17*(1-'1-输入参数'!$C$27*'1-输入参数'!$C$29)))/60/('1-输入参数'!$C$8*12))*'1-输入参数'!$C$10*12-('1-输入参数'!$C$7*(1-'1-输入参数'!$C$31)*'1-输入参数'!$C$11*12)-('2-现状基线'!$C$8*(('2-现状基线'!$C$4*(1-0.7)*('1-输入参数'!$C$16*(1-'1-输入参数'!$C$27*'1-输入参数'!$C$28)+'1-输入参数'!$C$17*(1-'1-输入参数'!$C$27*'1-输入参数'!$C$29)))/60/('1-输入参数'!$C$8*12))/'1-输入参数'!$C$6)-('2-现状基线'!$C$4*0.7*1.0)-'1-输入参数'!$C$35-'1-输入参数'!$C$37*'1-输入参数'!$C$38*12-'1-输入参数'!$C$39
A9: 0.8 | B9: =('2-现状基线'!$C$9)-(('2-现状基线'!$C$4*(1-0.8)*('1-输入参数'!$C$16*(1-'1-输入参数'!$C$27*'1-输入参数'!$C$28)+'1-输入参数'!$C$17*(1-'1-输入参数'!$C$27*'1-输入参数'!$C$29)))/60/('1-输入参数'!$C$8*12))*'1-输入参数'!$C$10*12-('1-输入参数'!$C$7*(1-'1-输入参数'!$C$31)*'1-输入参数'!$C$11*12)-('2-现状基线'!$C$8*(('2-现状基线'!$C$4*(1-0.8)*('1-输入参数'!$C$16*(1-'1-输入参数'!$C$27*'1-输入参数'!$C$28)+'1-输入参数'!$C$17*(1-'1-输入参数'!$C$27*'1-输入参数'!$C$29)))/60/('1-输入参数'!$C$8*12))/'1-输入参数'!$C$6)-('2-现状基线'!$C$4*0.8*0.1)-'1-输入参数'!$C$35-'1-输入参数'!$C$37*'1-输入参数'!$C$38*12-'1-输入参数'!$C$39 | C9: =('2-现状基线'!$C$9)-(('2-现状基线'!$C$4*(1-0.8)*('1-输入参数'!$C$16*(1-'1-输入参数'!$C$27*'1-输入参数'!$C$28)+'1-输入参数'!$C$17*(1-'1-输入参数'!$C$27*'1-输入参数'!$C$29)))/60/('1-输入参数'!$C$8*12))*'1-输入参数'!$C$10*12-('1-输入参数'!$C$7*(1-'1-输入参数'!$C$31)*'1-输入参数'!$C$11*12)-('2-现状基线'!$C$8*(('2-现状基线'!$C$4*(1-0.8)*('1-输入参数'!$C$16*(1-'1-输入参数'!$C$27*'1-输入参数'!$C$28)+'1-输入参数'!$C$17*(1-'1-输入参数'!$C$27*'1-输入参数'!$C$29)))/60/('1-输入参数'!$C$8*12))/'1-输入参数'!$C$6)-('2-现状基线'!$C$4*0.8*0.2)-'1-输入参数'!$C$35-'1-输入参数'!$C$37*'1-输入参数'!$C$38*12-'1-输入参数'!$C$39 | D9: =('2-现状基线'!$C$9)-(('2-现状基线'!$C$4*(1-0.8)*('1-输入参数'!$C$16*(1-'1-输入参数'!$C$27*'1-输入参数'!$C$28)+'1-输入参数'!$C$17*(1-'1-输入参数'!$C$27*'1-输入参数'!$C$29)))/60/('1-输入参数'!$C$8*12))*'1-输入参数'!$C$10*12-('1-输入参数'!$C$7*(1-'1-输入参数'!$C$31)*'1-输入参数'!$C$11*12)-('2-现状基线'!$C$8*(('2-现状基线'!$C$4*(1-0.8)*('1-输入参数'!$C$16*(1-'1-输入参数'!$C$27*'1-输入参数'!$C$28)+'1-输入参数'!$C$17*(1-'1-输入参数'!$C$27*'1-输入参数'!$C$29)))/60/('1-输入参数'!$C$8*12))/'1-输入参数'!$C$6)-('2-现状基线'!$C$4*0.8*0.3)-'1-输入参数'!$C$35-'1-输入参数'!$C$37*'1-输入参数'!$C$38*12-'1-输入参数'!$C$39 | E9: =('2-现状基线'!$C$9)-(('2-现状基线'!$C$4*(1-0.8)*('1-输入参数'!$C$16*(1-'1-输入参数'!$C$27*'1-输入参数'!$C$28)+'1-输入参数'!$C$17*(1-'1-输入参数'!$C$27*'1-输入参数'!$C$29)))/60/('1-输入参数'!$C$8*12))*'1-输入参数'!$C$10*12-('1-输入参数'!$C$7*(1-'1-输入参数'!$C$31)*'1-输入参数'!$C$11*12)-('2-现状基线'!$C$8*(('2-现状基线'!$C$4*(1-0.8)*('1-输入参数'!$C$16*(1-'1-输入参数'!$C$27*'1-输入参数'!$C$28)+'1-输入参数'!$C$17*(1-'1-输入参数'!$C$27*'1-输入参数'!$C$29)))/60/('1-输入参数'!$C$8*12))/'1-输入参数'!$C$6)-('2-现状基线'!$C$4*0.8*0.4)-'1-输入参数'!$C$35-'1-输入参数'!$C$37*'1-输入参数'!$C$38*12-'1-输入参数'!$C$39 | F9: =('2-现状基线'!$C$9)-(('2-现状基线'!$C$4*(1-0.8)*('1-输入参数'!$C$16*(1-'1-输入参数'!$C$27*'1-输入参数'!$C$28)+'1-输入参数'!$C$17*(1-'1-输入参数'!$C$27*'1-输入参数'!$C$29)))/60/('1-输入参数'!$C$8*12))*'1-输入参数'!$C$10*12-('1-输入参数'!$C$7*(1-'1-输入参数'!$C$31)*'1-输入参数'!$C$11*12)-('2-现状基线'!$C$8*(('2-现状基线'!$C$4*(1-0.8)*('1-输入参数'!$C$16*(1-'1-输入参数'!$C$27*'1-输入参数'!$C$28)+'1-输入参数'!$C$17*(1-'1-输入参数'!$C$27*'1-输入参数'!$C$29)))/60/('1-输入参数'!$C$8*12))/'1-输入参数'!$C$6)-('2-现状基线'!$C$4*0.8*0.5)-'1-输入参数'!$C$35-'1-输入参数'!$C$37*'1-输入参数'!$C$38*12-'1-输入参数'!$C$39 | G9: =('2-现状基线'!$C$9)-(('2-现状基线'!$C$4*(1-0.8)*('1-输入参数'!$C$16*(1-'1-输入参数'!$C$27*'1-输入参数'!$C$28)+'1-输入参数'!$C$17*(1-'1-输入参数'!$C$27*'1-输入参数'!$C$29)))/60/('1-输入参数'!$C$8*12))*'1-输入参数'!$C$10*12-('1-输入参数'!$C$7*(1-'1-输入参数'!$C$31)*'1-输入参数'!$C$11*12)-('2-现状基线'!$C$8*(('2-现状基线'!$C$4*(1-0.8)*('1-输入参数'!$C$16*(1-'1-输入参数'!$C$27*'1-输入参数'!$C$28)+'1-输入参数'!$C$17*(1-'1-输入参数'!$C$27*'1-输入参数'!$C$29)))/60/('1-输入参数'!$C$8*12))/'1-输入参数'!$C$6)-('2-现状基线'!$C$4*0.8*0.7)-'1-输入参数'!$C$35-'1-输入参数'!$C$37*'1-输入参数'!$C$38*12-'1-输入参数'!$C$39 | H9: =('2-现状基线'!$C$9)-(('2-现状基线'!$C$4*(1-0.8)*('1-输入参数'!$C$16*(1-'1-输入参数'!$C$27*'1-输入参数'!$C$28)+'1-输入参数'!$C$17*(1-'1-输入参数'!$C$27*'1-输入参数'!$C$29)))/60/('1-输入参数'!$C$8*12))*'1-输入参数'!$C$10*12-('1-输入参数'!$C$7*(1-'1-输入参数'!$C$31)*'1-输入参数'!$C$11*12)-('2-现状基线'!$C$8*(('2-现状基线'!$C$4*(1-0.8)*('1-输入参数'!$C$16*(1-'1-输入参数'!$C$27*'1-输入参数'!$C$28)+'1-输入参数'!$C$17*(1-'1-输入参数'!$C$27*'1-输入参数'!$C$29)))/60/('1-输入参数'!$C$8*12))/'1-输入参数'!$C$6)-('2-现状基线'!$C$4*0.8*1.0)-'1-输入参数'!$C$35-'1-输入参数'!$C$37*'1-输入参数'!$C$38*12-'1-输入参数'!$C$39
A10: 0.9 | B10: =('2-现状基线'!$C$9)-(('2-现状基线'!$C$4*(1-0.9)*('1-输入参数'!$C$16*(1-'1-输入参数'!$C$27*'1-输入参数'!$C$28)+'1-输入参数'!$C$17*(1-'1-输入参数'!$C$27*'1-输入参数'!$C$29)))/60/('1-输入参数'!$C$8*12))*'1-输入参数'!$C$10*12-('1-输入参数'!$C$7*(1-'1-输入参数'!$C$31)*'1-输入参数'!$C$11*12)-('2-现状基线'!$C$8*(('2-现状基线'!$C$4*(1-0.9)*('1-输入参数'!$C$16*(1-'1-输入参数'!$C$27*'1-输入参数'!$C$28)+'1-输入参数'!$C$17*(1-'1-输入参数'!$C$27*'1-输入参数'!$C$29)))/60/('1-输入参数'!$C$8*12))/'1-输入参数'!$C$6)-('2-现状基线'!$C$4*0.9*0.1)-'1-输入参数'!$C$35-'1-输入参数'!$C$37*'1-输入参数'!$C$38*12-'1-输入参数'!$C$39 | C10: =('2-现状基线'!$C$9)-(('2-现状基线'!$C$4*(1-0.9)*('1-输入参数'!$C$16*(1-'1-输入参数'!$C$27*'1-输入参数'!$C$28)+'1-输入参数'!$C$17*(1-'1-输入参数'!$C$27*'1-输入参数'!$C$29)))/60/('1-输入参数'!$C$8*12))*'1-输入参数'!$C$10*12-('1-输入参数'!$C$7*(1-'1-输入参数'!$C$31)*'1-输入参数'!$C$11*12)-('2-现状基线'!$C$8*(('2-现状基线'!$C$4*(1-0.9)*('1-输入参数'!$C$16*(1-'1-输入参数'!$C$27*'1-输入参数'!$C$28)+'1-输入参数'!$C$17*(1-'1-输入参数'!$C$27*'1-输入参数'!$C$29)))/60/('1-输入参数'!$C$8*12))/'1-输入参数'!$C$6)-('2-现状基线'!$C$4*0.9*0.2)-'1-输入参数'!$C$35-'1-输入参数'!$C$37*'1-输入参数'!$C$38*12-'1-输入参数'!$C$39 | D10: =('2-现状基线'!$C$9)-(('2-现状基线'!$C$4*(1-0.9)*('1-输入参数'!$C$16*(1-'1-输入参数'!$C$27*'1-输入参数'!$C$28)+'1-输入参数'!$C$17*(1-'1-输入参数'!$C$27*'1-输入参数'!$C$29)))/60/('1-输入参数'!$C$8*12))*'1-输入参数'!$C$10*12-('1-输入参数'!$C$7*(1-'1-输入参数'!$C$31)*'1-输入参数'!$C$11*12)-('2-现状基线'!$C$8*(('2-现状基线'!$C$4*(1-0.9)*('1-输入参数'!$C$16*(1-'1-输入参数'!$C$27*'1-输入参数'!$C$28)+'1-输入参数'!$C$17*(1-'1-输入参数'!$C$27*'1-输入参数'!$C$29)))/60/('1-输入参数'!$C$8*12))/'1-输入参数'!$C$6)-('2-现状基线'!$C$4*0.9*0.3)-'1-输入参数'!$C$35-'1-输入参数'!$C$37*'1-输入参数'!$C$38*12-'1-输入参数'!$C$39 | E10: =('2-现状基线'!$C$9)-(('2-现状基线'!$C$4*(1-0.9)*('1-输入参数'!$C$16*(1-'1-输入参数'!$C$27*'1-输入参数'!$C$28)+'1-输入参数'!$C$17*(1-'1-输入参数'!$C$27*'1-输入参数'!$C$29)))/60/('1-输入参数'!$C$8*12))*'1-输入参数'!$C$10*12-('1-输入参数'!$C$7*(1-'1-输入参数'!$C$31)*'1-输入参数'!$C$11*12)-('2-现状基线'!$C$8*(('2-现状基线'!$C$4*(1-0.9)*('1-输入参数'!$C$16*(1-'1-输入参数'!$C$27*'1-输入参数'!$C$28)+'1-输入参数'!$C$17*(1-'1-输入参数'!$C$27*'1-输入参数'!$C$29)))/60/('1-输入参数'!$C$8*12))/'1-输入参数'!$C$6)-('2-现状基线'!$C$4*0.9*0.4)-'1-输入参数'!$C$35-'1-输入参数'!$C$37*'1-输入参数'!$C$38*12-'1-输入参数'!$C$39 | F10: =('2-现状基线'!$C$9)-(('2-现状基线'!$C$4*(1-0.9)*('1-输入参数'!$C$16*(1-'1-输入参数'!$C$27*'1-输入参数'!$C$28)+'1-输入参数'!$C$17*(1-'1-输入参数'!$C$27*'1-输入参数'!$C$29)))/60/('1-输入参数'!$C$8*12))*'1-输入参数'!$C$10*12-('1-输入参数'!$C$7*(1-'1-输入参数'!$C$31)*'1-输入参数'!$C$11*12)-('2-现状基线'!$C$8*(('2-现状基线'!$C$4*(1-0.9)*('1-输入参数'!$C$16*(1-'1-输入参数'!$C$27*'1-输入参数'!$C$28)+'1-输入参数'!$C$17*(1-'1-输入参数'!$C$27*'1-输入参数'!$C$29)))/60/('1-输入参数'!$C$8*12))/'1-输入参数'!$C$6)-('2-现状基线'!$C$4*0.9*0.5)-'1-输入参数'!$C$35-'1-输入参数'!$C$37*'1-输入参数'!$C$38*12-'1-输入参数'!$C$39 | G10: =('2-现状基线'!$C$9)-(('2-现状基线'!$C$4*(1-0.9)*('1-输入参数'!$C$16*(1-'1-输入参数'!$C$27*'1-输入参数'!$C$28)+'1-输入参数'!$C$17*(1-'1-输入参数'!$C$27*'1-输入参数'!$C$29)))/60/('1-输入参数'!$C$8*12))*'1-输入参数'!$C$10*12-('1-输入参数'!$C$7*(1-'1-输入参数'!$C$31)*'1-输入参数'!$C$11*12)-('2-现状基线'!$C$8*(('2-现状基线'!$C$4*(1-0.9)*('1-输入参数'!$C$16*(1-'1-输入参数'!$C$27*'1-输入参数'!$C$28)+'1-输入参数'!$C$17*(1-'1-输入参数'!$C$27*'1-输入参数'!$C$29)))/60/('1-输入参数'!$C$8*12))/'1-输入参数'!$C$6)-('2-现状基线'!$C$4*0.9*0.7)-'1-输入参数'!$C$35-'1-输入参数'!$C$37*'1-输入参数'!$C$38*12-'1-输入参数'!$C$39 | H10: =('2-现状基线'!$C$9)-(('2-现状基线'!$C$4*(1-0.9)*('1-输入参数'!$C$16*(1-'1-输入参数'!$C$27*'1-输入参数'!$C$28)+'1-输入参数'!$C$17*(1-'1-输入参数'!$C$27*'1-输入参数'!$C$29)))/60/('1-输入参数'!$C$8*12))*'1-输入参数'!$C$10*12-('1-输入参数'!$C$7*(1-'1-输入参数'!$C$31)*'1-输入参数'!$C$11*12)-('2-现状基线'!$C$8*(('2-现状基线'!$C$4*(1-0.9)*('1-输入参数'!$C$16*(1-'1-输入参数'!$C$27*'1-输入参数'!$C$28)+'1-输入参数'!$C$17*(1-'1-输入参数'!$C$27*'1-输入参数'!$C$29)))/60/('1-输入参数'!$C$8*12))/'1-输入参数'!$C$6)-('2-现状基线'!$C$4*0.9*1.0)-'1-输入参数'!$C$35-'1-输入参数'!$C$37*'1-输入参数'!$C$38*12-'1-输入参数'!$C$39
A13: 解读：绿色区域是你应该冲的目标；如果现实只能落在红色区域，说明项目 ROI 不成立，要么降投入、要么扩场景。

Sheet 7-Dashboard
A1: 7. 汇报 Dashboard（一页纸）
B3: —— 现状基线 —— | E3: —— Y3 改造后 ——
B4: 年会话量 | C4: ='2-现状基线'!$C$4 | E4: AI 承接率 | F4: ='1-输入参数'!$C$24
B5: 坐席数 | C5: ='1-输入参数'!$C$6 | E5: 改造后总成本 | F5: ='3-AI改造后测算'!D21
B6: 年人工总成本 | C6: ='2-现状基线'!$C$9 | E6: 年度节省 | F6: ='3-AI改造后测算'!D23
B7: 单次会话成本 | C7: ='2-现状基线'!$C$10 | E7: 降本率 | F7: ='3-AI改造后测算'!D24
B8: FCR | C8: ='1-输入参数'!$C$18 | E8: 新单次会话成本 | F8: ='3-AI改造后测算'!D25
B9: 质检覆盖率 | C9: ='1-输入参数'!$C$19 | E9: FCR | F9: ='1-输入参数'!$C$18+'1-输入参数'!$C$32
B10: CSAT | C10: ='1-输入参数'!$C$20 | E10: CSAT | F10: ='1-输入参数'!$C$20+'1-输入参数'!$C$42
B13: 关键结论（Executive Summary）
B14: 1. 项目总投入 | E14: ='1-输入参数'!$C$36
B15: 2. 三年总节省 | E15: =SUM('3-AI改造后测算'!B23,'3-AI改造后测算'!C23,'3-AI改造后测算'!D23)
B16: 3. NPV | E16: ='5-三年现金流ROI'!E10
B17: 4. IRR | E17: =IFERROR('5-三年现金流ROI'!B14,"N/A")
B18: 5. 静态回收期（年） | E18: ='5-三年现金流ROI'!B15
B19: 6. 单次成本降幅 | E19: =1-'3-AI改造后测算'!D25/'2-现状基线'!$C$10
